<robot name = "mycar">
    <link name = "footprint_link">
        <visual>
            <geometry>
                <box size = "0.001 0.001 0.001" />
            </geometry>
            <origin xyz=" 0 0 0" rpy="0 0 0 " />
            <material name = "car_color">
                <color rgba="0 1 0 0.9" />
            </material>
        </visual>
    </link>

    <link name = "base_link">
        <visual>
            <!-- shape -->
            <geometry>
                <box size = "0.5 0.5 0.5" />
            </geometry>
            <origin xyz="0 0 0" rpy="0  0 0" />
            <!-- color -->
            <material name = "car_color">
                <color rgba= "0 0 1 0.5" />
            </material>
        </visual>
    </link>

    <link name = "camera_link">
        <visual>
            <geometry>
                <box size = "0.2 0.2 0.2" />
            </geometry>
            <origin xyz=" 0 0 0" rpy="0 0 0 " />
            <material name = "car_color">
                <color rgba="0 1 0 0.9" />
            </material>
        </visual>
    </link>
    
    <joint name = "footprint" type = "fixed">
        <parent link = "footprint_link" />
        <child link = "base_link" />
        <origin xyz="0 0 0.25" rpy="0 0 0" />
    </joint>

    <joint name = "camera_to_base" type = "continuous">
        <parent link = "base_link" />
        <child link = "camera_link" />
        <origin xyz="0.15 0 0.35" rpy="0 0 0" />
        <axis xyz= "0 0 1" />
    </joint>
</robot>

