<robot name = "mycar">

    <link name = "footprint_link">
        <visual>
            <geometry>
                <box size = "0.001 0.001 0.001" />
            </geometry>
            <origin xyz=" 0 0 0" rpy="0 0 0 " />
            <material name = "car_color">
                <color rgba="0.0 1.0 0.0 0.9" />
            </material>
        </visual>
    </link>

    <link name = "base_link">

        <visual>
            <!-- shape -->
            <geometry>
                <cylinder radius="0.1" length="0.08" />
            </geometry>
            <origin xyz="0 0 0" rpy="0  0 0" />
            <!-- color -->
            <material name = "base_link_color">
                <color rgba= "1.0 0.5 0.2 0.5" />
            </material>
        </visual>
    </link>

    <link name = "left_wheel_link">
        <visual>
            <geometry>
                <cylinder radius = "0.0325"  length="0.015" />
            </geometry>
            <origin xyz=" 0 0 0" rpy="1.5708 0 0 " />
            <material name = "left_wheel_color">
                <color rgba="0 0 0 0.5" />
            </material>
        </visual>
    </link>
    
    <link name = "right_wheel_link">
        <visual>
            <geometry>
                <cylinder radius = "0.0325"  length="0.015" />
            </geometry>
            <origin xyz=" 0 0 0" rpy="1.5708 0 0 " />
            <material name = "right_wheel_color">
                <color rgba="0 0 0 0.5" />
            </material>
        </visual>
    </link>

    <link name = "front_wheel_link">
        <visual>
            <geometry>
                <sphere radius = "0.0075" />
            </geometry>
            <origin xyz=" 0 0 0" rpy="0 0 0 " />
            <material name = "front_wheel_color">
                <color rgba="1 0 0 0.5" />
            </material>
        </visual>
    </link>


    <joint name = "footprint_base" type = "fixed">
        <parent link = "footprint_link" />
        <child link = "base_link" />
        <origin xyz="0 0 0.055" rpy="0 0 0" />
    </joint>

    <joint name = "base_left_wheel" type = "continuous">
        <parent link = "base_link" />
        <child link = "left_wheel_link" />
        <origin xyz="0 0.1 -0.0225" rpy="0 0 0" />
        <axis xyz= "0 1 0" />
    </joint>

    <joint name = "base_right_wheel" type = "continuous">
        <parent link = "base_link" />
        <child link = "right_wheel_link" />
        <origin xyz="0 -0.1 -0.0225" rpy="0 0 0" />
        <axis xyz= "0 1 0" />
    </joint>

     <joint name = "base_front_wheel" type = "continuous">
        <parent link = "base_link" />
        <child link = "front_wheel_link" />
        <origin xyz="0.08 0 -0.0475" rpy="0 0 0" />
        <axis xyz= "1 1 0" />
    </joint>

</robot>